Workbook

Sheet Master_Data
A1: Inventory Items at Jean-Marie Bourjolly's Restaurant With ABC Analysis
A3: Code-Item | B3: Inventory Item | C3: $ Value/Case | D3: Ordered/Week | E3: Quantity/Year | F3: Annual Dollar Volume ($) | G3: % Volume Total | H3: %Cumulatif | I3: ABC Category | J3: Demand (year) | K3: Holding Cost (h)$ | L3: EOQ | M3: ROP | N3: Daily Demand
A4: Item 1 | B4: Fish filets | C4: 143 | D4: 10 | E4: =Table1[[#This Row],[Ordered/Week]]*52 -> 520 | F4: =Table1[[#This Row],[Quantity/Year]]*Table1[[#This Row],[$ Value/Case]] -> 74360 | G4: =Table1[[#This Row],[Annual Dollar Volume ($)]]/Table1[[#Totals],[Annual Dollar Volume ($)]]*100 -> 17.54386 | H4: =Table1[[#This Row],[% Volume Total]] -> 17.54386 | I4: =IF(H4<=80, "A", IF(H4<=95, "B", "C")) -> A | J4: =Table1[[#This Row],[Ordered/Week]]*52 -> 520 | K4: =Table1[[#This Row],[$ Value/Case]]*0.2 -> 28.6 | L4: =ROUND(SQRT((2 * Table1[[#This Row],[Demand (year)]]* 20) / Table1[[#This Row],[Holding Cost (h)$]]), 0) -> 27 | M4: =ROUND(((Table1[[#This Row],[Demand (year)]] /365)*3), 0) -> 4 | N4: =J4/365 -> 1.4246575
A5: Item 2 | B5: French fries | C5: 43 | D5: 32 | E5: =Table1[[#This Row],[Ordered/Week]]*52 -> 1664 | F5: =Table1[[#This Row],[Quantity/Year]]*Table1[[#This Row],[$ Value/Case]] -> 71552 | G5: =Table1[[#This Row],[Annual Dollar Volume ($)]]/Table1[[#Totals],[Annual Dollar Volume ($)]]*100 -> 16.881364 | H5: =Table1[[#This Row],[% Volume Total]]+H4 -> 34.425224 | I5: =IF(H5<=80, "A", IF(H5<=95, "B", "C")) -> A | J5: =Table1[[#This Row],[Ordered/Week]]*52 -> 1664 | K5: =Table1[[#This Row],[$ Value/Case]]*0.2 -> 8.6 | L5: =ROUND(SQRT((2 * Table1[[#This Row],[Demand (year)]]* 20) / Table1[[#This Row],[Holding Cost (h)$]]), 0) -> 88 | M5: =ROUND(((Table1[[#This Row],[Demand (year)]] /365)*3), 0) -> 14 | N5: =J5/365 -> 4.5589041
A6: Item 3 | B6: Chickens | C6: 75 | D6: 14 | E6: =Table1[[#This Row],[Ordered/Week]]*52 -> 728 | F6: =Table1[[#This Row],[Quantity/Year]]*Table1[[#This Row],[$ Value/Case]] -> 54600 | G6: =Table1[[#This Row],[Annual Dollar Volume ($)]]/Table1[[#Totals],[Annual Dollar Volume ($)]]*100 -> 12.881855 | H6: =Table1[[#This Row],[% Volume Total]]+H5 -> 47.307079 | I6: =IF(H6<=80, "A", IF(H6<=95, "B", "C")) -> A | J6: =Table1[[#This Row],[Ordered/Week]]*52 -> 728 | K6: =Table1[[#This Row],[$ Value/Case]]*0.2 -> 15 | L6: =ROUND(SQRT((2 * Table1[[#This Row],[Demand (year)]]* 20) / Table1[[#This Row],[Holding Cost (h)$]]), 0) -> 44 | M6: =ROUND(((Table1[[#This Row],[Demand (year)]] /365)*3), 0) -> 6 | N6: =J6/365 -> 1.9945205
A7: Item 4 | B7: Prime rib roasts | C7: 166 | D7: 6 | E7: =Table1[[#This Row],[Ordered/Week]]*52 -> 312 | F7: =Table1[[#This Row],[Quantity/Year]]*Table1[[#This Row],[$ Value/Case]] -> 51792 | G7: =Table1[[#This Row],[Annual Dollar Volume ($)]]/Table1[[#Totals],[Annual Dollar Volume ($)]]*100 -> 12.21936 | H7: =Table1[[#This Row],[% Volume Total]]+H6 -> 59.526438 | I7: =IF(H7<=80, "A", IF(H7<=95, "B", "C")) -> A | J7: =Table1[[#This Row],[Ordered/Week]]*52 -> 312 | K7: =Table1[[#This Row],[$ Value/Case]]*0.2 -> 33.2 | L7: =ROUND(SQRT((2 * Table1[[#This Row],[Demand (year)]]* 20) / Table1[[#This Row],[Holding Cost (h)$]]), 0) -> 19 | M7: =ROUND(((Table1[[#This Row],[Demand (year)]] /365)*3), 0) -> 3 | N7: =J7/365 -> 0.85479452
A8: Item 5 | B8: Lettuce (case) | C8: 35 | D8: 24 | E8: =Table1[[#This Row],[Ordered/Week]]*52 -> 1248 | F8: =Table1[[#This Row],[Quantity/Year]]*Table1[[#This Row],[$ Value/Case]] -> 43680 | G8: =Table1[[#This Row],[Annual Dollar Volume ($)]]/Table1[[#Totals],[Annual Dollar Volume ($)]]*100 -> 10.305484 | H8: =Table1[[#This Row],[% Volume Total]]+H7 -> 69.831922 | I8: =IF(H8<=80, "A", IF(H8<=95, "B", "C")) -> A | J8: =Table1[[#This Row],[Ordered/Week]]*52 -> 1248 | K8: =Table1[[#This Row],[$ Value/Case]]*0.2 -> 7 | L8: =ROUND(SQRT((2 * Table1[[#This Row],[Demand (year)]]* 20) / Table1[[#This Row],[Holding Cost (h)$]]), 0) -> 84 | M8: =ROUND(((Table1[[#This Row],[Demand (year)]] /365)*3), 0) -> 10 | N8: =J8/365 -> 3.4191781
A9: Item 6 | B9: Lobster tail | C9: 245 | D9: 3 | E9: =Table1[[#This Row],[Ordered/Week]]*52 -> 156 | F9: =Table1[[#This Row],[Quantity/Year]]*Table1[[#This Row],[$ Value/Case]] -> 38220 | G9: =Table1[[#This Row],[Annual Dollar Volume ($)]]/Table1[[#Totals],[Annual Dollar Volume ($)]]*100 -> 9.0172985 | H9: =Table1[[#This Row],[% Volume Total]]+H8 -> 78.849221 | I9: =IF(H9<=80, "A", IF(H9<=95, "B", "C")) -> A | J9: =Table1[[#This Row],[Ordered/Week]]*52 -> 156 | K9: =Table1[[#This Row],[$ Value/Case]]*0.2 -> 49 | L9: =ROUND(SQRT((2 * Table1[[#This Row],[Demand (year)]]* 20) / Table1[[#This Row],[Holding Cost (h)$]]), 0) -> 11 | M9: =ROUND(((Table1[[#This Row],[Demand (year)]] /365)*3), 0) -> 1 | N9: =J9/365 -> 0.42739726
A10: Item 7 | B10: Ribeye Steak | C10: 135 | D10: 3 | E10: =Table1[[#This Row],[Ordered/Week]]*52 -> 156 | F10: =Table1[[#This Row],[Quantity/Year]]*Table1[[#This Row],[$ Value/Case]] -> 21060 | G10: =Table1[[#This Row],[Annual Dollar Volume ($)]]/Table1[[#Totals],[Annual Dollar Volume ($)]]*100 -> 4.9687155 | H10: =Table1[[#This Row],[% Volume Total]]+H9 -> 83.817936 | I10: =IF(H10<=80, "A", IF(H10<=95, "B", "C")) -> B | J10: =Table1[[#This Row],[Ordered/Week]]*52 -> 156 | K10: =Table1[[#This Row],[$ Value/Case]]*0.2 -> 27 | L10: =ROUND(SQRT((2 * Table1[[#This Row],[Demand (year)]]* 20) / Table1[[#This Row],[Holding Cost (h)$]]), 0) -> 15 | M10: =ROUND(((Table1[[#This Row],[Demand (year)]] /365)*3), 0) -> 1 | N10: =J10/365 -> 0.42739726
A11: Item 8 | B11: Bacon | C11: 56 | D11: 5 | E11: =Table1[[#This Row],[Ordered/Week]]*52 -> 260 | F11: =Table1[[#This Row],[Quantity/Year]]*Table1[[#This Row],[$ Value/Case]] -> 14560 | G11: =Table1[[#This Row],[Annual Dollar Volume ($)]]/Table1[[#Totals],[Annual Dollar Volume ($)]]*100 -> 3.4351613 | H11: =Table1[[#This Row],[% Volume Total]]+H10 -> 87.253098 | I11: =IF(H11<=80, "A", IF(H11<=95, "B", "C")) -> B | J11: =Table1[[#This Row],[Ordered/Week]]*52 -> 260 | K11: =Table1[[#This Row],[$ Value/Case]]*0.2 -> 11.2 | L11: =ROUND(SQRT((2 * Table1[[#This Row],[Demand (year)]]* 20) / Table1[[#This Row],[Holding Cost (h)$]]), 0) -> 30 | M11: =ROUND(((Table1[[#This Row],[Demand (year)]] /365)*3), 0) -> 2 | N11: =J11/365 -> 0.71232877
A12: Item 9 | B12: Pasta | C12: 23 | D12: 12 | E12: =Table1[[#This Row],[Ordered/Week]]*52 -> 624 | F12: =Table1[[#This Row],[Quantity/Year]]*Table1[[#This Row],[$ Value/Case]] -> 14352 | G12: =Table1[[#This Row],[Annual Dollar Volume ($)]]/Table1[[#Totals],[Annual Dollar Volume ($)]]*100 -> 3.3860876 | H12: =Table1[[#This Row],[% Volume Total]]+H11 -> 90.639185 | I12: =IF(H12<=80, "A", IF(H12<=95, "B", "C")) -> B | J12: =Table1[[#This Row],[Ordered/Week]]*52 -> 624 | K12: =Table1[[#This Row],[$ Value/Case]]*0.2 -> 4.6 | L12: =ROUND(SQRT((2 * Table1[[#This Row],[Demand (year)]]* 20) / Table1[[#This Row],[Holding Cost (h)$]]), 0) -> 74 | M12: =ROUND(((Table1[[#This Row],[Demand (year)]] /365)*3), 0) -> 5 | N12: =J12/365 -> 1.709589
A13: Item 10 | B13: Tomato Sauce | C13: 23 | D13: 11 | E13: =Table1[[#This Row],[Ordered/Week]]*52 -> 572 | F13: =Table1[[#This Row],[Quantity/Year]]*Table1[[#This Row],[$ Value/Case]] -> 13156 | G13: =Table1[[#This Row],[Annual Dollar Volume ($)]]/Table1[[#Totals],[Annual Dollar Volume ($)]]*100 -> 3.1039136 | H13: =Table1[[#This Row],[% Volume Total]]+H12 -> 93.743099 | I13: =IF(H13<=80, "A", IF(H13<=95, "B", "C")) -> B | J13: =Table1[[#This Row],[Ordered/Week]]*52 -> 572 | K13: =Table1[[#This Row],[$ Value/Case]]*0.2 -> 4.6 | L13: =ROUND(SQRT((2 * Table1[[#This Row],[Demand (year)]]* 20) / Table1[[#This Row],[Holding Cost (h)$]]), 0) -> 71 | M13: =ROUND(((Table1[[#This Row],[Demand (year)]] /365)*3), 0) -> 5 | N13: =J13/365 -> 1.5671233
A14: Item 11 | B14: Table cloth | C14: 32 | D14: 5 | E14: =Table1[[#This Row],[Ordered/Week]]*52 -> 260 | F14: =Table1[[#This Row],[Quantity/Year]]*Table1[[#This Row],[$ Value/Case]] -> 8320 | G14: =Table1[[#This Row],[Annual Dollar Volume ($)]]/Table1[[#Totals],[Annual Dollar Volume ($)]]*100 -> 1.9629493 | H14: =Table1[[#This Row],[% Volume Total]]+H13 -> 95.706048 | I14: =IF(H14<=80, "A", IF(H14<=95, "B", "C")) -> C | J14: =Table1[[#This Row],[Ordered/Week]]*52 -> 260 | K14: =Table1[[#This Row],[$ Value/Case]]*0.2 -> 6.4 | L14: =ROUND(SQRT((2 * Table1[[#This Row],[Demand (year)]]* 20) / Table1[[#This Row],[Holding Cost (h)$]]), 0) -> 40 | M14: =ROUND(((Table1[[#This Row],[Demand (year)]] /365)*3), 0) -> 2 | N14: =J14/365 -> 0.71232877
A15: Item 12 | B15: Eggs (case) | C15: 22 | D15: 7 | E15: =Table1[[#This Row],[Ordered/Week]]*52 -> 364 | F15: =Table1[[#This Row],[Quantity/Year]]*Table1[[#This Row],[$ Value/Case]] -> 8008 | G15: =Table1[[#This Row],[Annual Dollar Volume ($)]]/Table1[[#Totals],[Annual Dollar Volume ($)]]*100 -> 1.8893387 | H15: =Table1[[#This Row],[% Volume Total]]+H14 -> 97.595387 | I15: =IF(H15<=80, "A", IF(H15<=95, "B", "C")) -> C | J15: =Table1[[#This Row],[Ordered/Week]]*52 -> 364 | K15: =Table1[[#This Row],[$ Value/Case]]*0.2 -> 4.4 | L15: =ROUND(SQRT((2 * Table1[[#This Row],[Demand (year)]]* 20) / Table1[[#This Row],[Holding Cost (h)$]]), 0) -> 58 | M15: =ROUND(((Table1[[#This Row],[Demand (year)]] /365)*3), 0) -> 3 | N15: =J15/365 -> 0.99726027
A16: Item 13 | B16: Oil | C16: 28 | D16: 2 | E16: =Table1[[#This Row],[Ordered/Week]]*52 -> 104 | F16: =Table1[[#This Row],[Quantity/Year]]*Table1[[#This Row],[$ Value/Case]] -> 2912 | G16: =Table1[[#This Row],[Annual Dollar Volume ($)]]/Table1[[#Totals],[Annual Dollar Volume ($)]]*100 -> 0.68703227 | H16: =Table1[[#This Row],[% Volume Total]]+H15 -> 98.282419 | I16: =IF(H16<=80, "A", IF(H16<=95, "B", "C")) -> C | J16: =Table1[[#This Row],[Ordered/Week]]*52 -> 104 | K16: =Table1[[#This Row],[$ Value/Case]]*0.2 -> 5.6 | L16: =ROUND(SQRT((2 * Table1[[#This Row],[Demand (year)]]* 20) / Table1[[#This Row],[Holding Cost (h)$]]), 0) -> 27 | M16: =ROUND(((Table1[[#This Row],[Demand (year)]] /365)*3), 0) -> 1 | N16: =J16/365 -> 0.28493151
... A23: Item 20 | B23: Salt | C23: 3 | D23: 2 | E23: =Table1[[#This Row],[Ordered/Week]]*52 -> 104 | F23: =Table1[[#This Row],[Quantity/Year]]*Table1[[#This Row],[$ Value/Case]] -> 312 | G23: =Table1[[#This Row],[Annual Dollar Volume ($)]]/Table1[[#Totals],[Annual Dollar Volume ($)]]*100 -> 0.0736106 | H23: =Table1[[#This Row],[% Volume Total]]+H22 -> 100 | I23: =IF(H23<=80, "A", IF(H23<=95, "B", "C")) -> C | J23: =Table1[[#This Row],[Ordered/Week]]*52 -> 104 | K23: =Table1[[#This Row],[$ Value/Case]]*0.2 -> 0.6 | L23: =ROUND(SQRT((2 * Table1[[#This Row],[Demand (year)]]* 20) / Table1[[#This Row],[Holding Cost (h)$]]), 0) -> 83 | M23: =ROUND(((Table1[[#This Row],[Demand (year)]] /365)*3), 0) -> 1 | N23: =J23/365 -> 0.28493151
B24: Total ($) | F24: =SUM(Table1[Annual Dollar Volume ($)]) -> 423852
A27: Inventory Item | B27: Annual Dollar Volume ($) | C27: %Cumulatif
A28: Fish filets | B28: 74360 | C28: 17.54386
A29: French fries | B29: 71552 | C29: 34.425224
A30: Chickens | B30: 54600 | C30: 47.307079
A31: Prime rib roasts | B31: 51792 | C31: 59.526438
A32: Lettuce (case) | B32: 43680 | C32: 69.831922
A33: Lobster tail | B33: 38220 | C33: 78.849221
A34: Ribeye Steak | B34: 21060 | C34: 83.817936
A35: Bacon | B35: 14560 | C35: 87.253098
A36: Pasta | B36: 14352 | C36: 90.639185
A37: Tomato Sauce | B37: 13156 | C37: 93.743099
A38: Table cloth | B38: 8320 | C38: 95.706048
A39: Eggs (case) | B39: 8008 | C39: 97.595387
... A47: Salt | B47: 312 | C47: 100
A48: Total ($) | B48: 423852
A51: Day | B51: Inventory Level | C51: ROP Line
A52: 0 | B52: =Dashboard!$O$9 -> 88 | C52: =Dashboard!$O$10 -> 14
A53: 1 | B53: =IF(B52<=0, Dashboard!$O$9, B52-Dashboard!$O$11) -> 83.441096 | C53: =Dashboard!$O$10 -> 14
A54: 2 | B54: =IF(B53<=0, Dashboard!$O$9, B53-Dashboard!$O$11) -> 78.882192 | C54: =Dashboard!$O$10 -> 14
A55: 3 | B55: =IF(B54<=0, Dashboard!$O$9, B54-Dashboard!$O$11) -> 74.323288 | C55: =Dashboard!$O$10 -> 14
A56: 4 | B56: =IF(B55<=0, Dashboard!$O$9, B55-Dashboard!$O$11) -> 69.764384 | C56: =Dashboard!$O$10 -> 14
A57: 5 | B57: =IF(B56<=0, Dashboard!$O$9, B56-Dashboard!$O$11) -> 65.205479 | C57: =Dashboard!$O$10 -> 14
A58: 6 | B58: =IF(B57<=0, Dashboard!$O$9, B57-Dashboard!$O$11) -> 60.646575 | C58: =Dashboard!$O$10 -> 14
...

Sheet Dashboard
N7: Select Item | O7: Item 2
N8: Inventory Item | O8: =VLOOKUP(O7, Table1[], 2, FALSE) -> French fries
N9: EOQ | O9: =VLOOKUP(O7, Table1[], 12, FALSE) -> 88
N10: ROP | O10: =VLOOKUP(O7, Table1[], 13, FALSE) -> 14
N11: Daily Demand | O11: =VLOOKUP(O7, Table1[], 14, FALSE) -> 4.5589041
N14: A | Q14: B | T14: C
N17: =B56 -> 6 | Q17: =B57 -> 4 | T17: =B58 -> 10
A50: BY: NUR LAILA KAMALIYAH
B55: Count | C55: % Share
A56: A | B56: =COUNTIF(Master_Data!I:I, "A") -> 6 | C56: =B56/SUM(B$56:$B$58) -> 0.3
A57: B | B57: =COUNTIF(Master_Data!I:I, "B") -> 4 | C57: =B57/SUM(B$56:$B$58) -> 0.2
A58: C | B58: =COUNTIF(Master_Data!I:I, "C") -> 10 | C58: =B58/SUM(B$56:$B$58) -> 0.5
